Workbook

Sheet data_wide_f
A1: country | B1: year | C1: GDP | D1: inbound | E1: Political Stability | F1: exchange rate | G1: Rule of Law: Estimate
A2: Azerbaijan | B2: 2002 | C2: 8.79 | D2: 13.63 | E2: -1.19 | F2: -0.03 | G2: -0.96
A3: Azerbaijan | B3: 2003 | C3: 8.88 | D3: 13.85 | E3: -0.95 | F3: -0.02 | G3: -0.88
A4: Azerbaijan | B4: 2004 | C4: 8.96 | D4: 14.06 | E4: -1.06 | F4: -0.02 | G4: -0.90
A5: Azerbaijan | B5: 2005 | C5: 9.20 | D5: 13.98 | E5: -1.12 | F5: -0.06 | G5: -0.79
A6: Azerbaijan | B6: 2006 | C6: 9.49 | D6: 13.99 | E6: -1.09 | F6: -0.11 | G6: -0.89
A7: Azerbaijan | B7: 2007 | C7: 9.70 | D7: 14.10 | E7: -0.63 | F7: -0.15 | G7: -0.88
A8: Azerbaijan | B8: 2008 | C8: 9.78 | D8: 14.46 | E8: -0.33 | F8: -0.20 | G8: -0.84
A9: Azerbaijan | B9: 2009 | C9: 9.85 | D9: 14.42 | E9: -0.28 | F9: -0.22 | G9: -0.88
A10: Azerbaijan | B10: 2010 | C10: 9.88 | D10: 14.49 | E10: -0.24 | F10: -0.22 | G10: -0.89
A11: Azerbaijan | B11: 2011 | C11: 9.87 | D11: 14.62 | E11: -0.53 | F11: -0.24 | G11: -0.94
A12: Azerbaijan | B12: 2012 | C12: 9.88 | D12: 14.73 | E12: -0.72 | F12: -0.24 | G12: -0.88
A13: Azerbaijan | B13: 2013 | C13: 9.92 | D13: 14.74 | E13: -0.41 | F13: -0.24 | G13: -0.76
... A199: Türkiye | B199: 2019 | C199: 10.24 | D199: 17.76 | E199: -1.38 | F199: 1.74 | G199: -0.35

Sheet data_ln
A1: =raw!A1 -> country | B1: =raw!B1 -> country_id | C1: =raw!C1 -> variable | D1: =raw!D1 -> 2002 | E1: =raw!E1 -> 2003 | F1: =raw!F1 -> 2004 | G1: =raw!G1 -> 2005 | H1: =raw!H1 -> 2006 | ... U1: =raw!U1 -> 2019
A2: =raw!A2 -> Azerbaijan | B2: =raw!B2 -> 🇦🇿 | C2: =raw!C2 -> GDP per capita, PPP (constant 2021 international $) | D2: =LN(raw!D2) -> 8.794773 | E2: =LN(raw!E2) -> 8.8843986 | F2: =LN(raw!F2) -> 8.9641477 | G2: =LN(raw!G2) -> 9.2004846 | H2: =LN(raw!H2) -> 9.4858928 | I2: =LN(raw!I2) -> 9.6976978 | J2: =LN(raw!J2) -> 9.7788855 | K2: =LN(raw!K2) -> 9.847017 | ... U2: =LN(raw!U2) -> 9.9096044
A3: =raw!A3 -> Azerbaijan | B3: =raw!B3 -> 🇦🇿 | C3: =raw!C3 -> International tourism, number of arrivals | D3: =LN(raw!D3) -> 13.633989 | E3: =LN(raw!E3) -> 13.852806 | F3: =LN(raw!F3) -> 14.061589 | G3: =LN(raw!G3) -> 13.978479 | H3: =LN(raw!H3) -> 13.99282 | I3: =LN(raw!I3) -> 14.102943 | J3: =LN(raw!J3) -> 14.456838 | K3: =LN(raw!K3) -> 14.419827 | ... U3: =LN(raw!U3) -> 14.969242
A4: =raw!A4 -> Azerbaijan | B4: =raw!B4 -> 🇦🇿 | C4: =raw!C4 -> Political Stability and Absence of Violence/Terrorism: Estimate | D4: =raw!D4 -> -1.185365 | E4: =raw!E4 -> -0.94810039 | F4: =raw!F4 -> -1.0598111 | G4: =raw!G4 -> -1.1248194 | H4: =raw!H4 -> -1.0926824 | ... U4: =raw!U4 -> -0.69341147
A5: =raw!A5 -> Azerbaijan | B5: =raw!B5 -> 🇦🇿 | C5: =raw!C5 -> Official exchange rate (LCU per US$, period average) | D5: =LN(raw!D5) -> -0.028230593 | E5: =LN(raw!E5) -> -0.018015306 | F5: =LN(raw!F5) -> -0.017455973 | G5: =LN(raw!G5) -> -0.056124948 | H5: =LN(raw!H5) -> -0.1126705 | I5: =LN(raw!I5) -> -0.15300689 | J5: =LN(raw!J5) -> -0.19647779 | K5: =LN(raw!K5) -> -0.21842553 | ... U5: =LN(raw!U5) -> 0.53062825
A6: Azerbaijan | B6: 🇦🇿 | C6: ='Rule of Law'!C20 -> Rule of Law: Estimate | D6: ='Rule of Law'!AU20 -> -0.96419722 | E6: ='Rule of Law'!AV20 -> -0.88464475 | F6: ='Rule of Law'!AW20 -> -0.90051848 | G6: ='Rule of Law'!AX20 -> -0.79261243 | H6: ='Rule of Law'!AY20 -> -0.88592923 | I6: ='Rule of Law'!AZ20 -> -0.88002038 | J6: ='Rule of Law'!BA20 -> -0.83616048 | K6: ='Rule of Law'!BB20 -> -0.87917602 | ... U6: ='Rule of Law'!BL20 -> -0.61042804
A7: =raw!A7 -> China | B7: =raw!B7 -> 🇨🇳 | C7: =raw!C7 -> GDP per capita, PPP (constant 2021 international $) | D7: =LN(raw!D7) -> 8.4448153 | E7: =LN(raw!E7) -> 8.5342426 | F7: =LN(raw!F7) -> 8.6246458 | G7: =LN(raw!G7) -> 8.7266732 | H7: =LN(raw!H7) -> 8.8408346 | I7: =LN(raw!I7) -> 8.9686632 | J7: =LN(raw!J7) -> 9.0556688 | K7: =LN(raw!K7) -> 9.140524 | ... U7: =LN(raw!U7) -> 9.8236485
A8: =raw!A8 -> China | B8: =raw!B8 -> 🇨🇳 | C8: =raw!C8 -> International tourism, number of arrivals | D8: =LN(raw!D8) -> 18.399539 | E8: =LN(raw!E8) -> 18.333618 | F8: =LN(raw!F8) -> 18.507207 | G8: =LN(raw!G8) -> 18.605433 | H8: =LN(raw!H8) -> 18.64336 | I8: =LN(raw!I8) -> 18.69735 | J8: =LN(raw!J8) -> 18.683253 | K8: =LN(raw!K8) -> 18.655563 | ... U8: =LN(raw!U8) -> 18.906422
A9: =raw!A9 -> China | B9: =raw!B9 -> 🇨🇳 | C9: =raw!C9 -> Political Stability and Absence of Violence/Terrorism: Estimate | D9: =raw!D9 -> -0.32762718 | E9: =raw!E9 -> -0.56535792 | F9: =raw!F9 -> -0.39068067 | G9: =raw!G9 -> -0.50175661 | H9: =raw!H9 -> -0.54003012 | ... U9: =raw!U9 -> -0.25978068
A10: =raw!A10 -> China | B10: =raw!B10 -> 🇨🇳 | C10: =raw!C10 -> Official exchange rate (LCU per US$, period average) | D10: =LN(raw!D10) -> 2.1134754 | E10: =LN(raw!E10) -> 2.113485 | F10: =LN(raw!F10) -> 2.1134565 | G10: =LN(raw!G10) -> 2.1034408 | H10: =LN(raw!H10) -> 2.0761158 | I10: =LN(raw!I10) -> 2.0291389 | J10: =LN(raw!J10) -> 1.9385481 | K10: =LN(raw!K10) -> 1.921532 | ... U10: =LN(raw!U10) -> 1.9327359
A11: China | B11: 🇨🇳 | C11: =raw!C11 -> Rule of Law: Estimate | D11: =raw!D11 -> -0.96419722 | E11: =raw!E11 -> -0.88464475 | F11: =raw!F11 -> -0.90051848 | G11: =raw!G11 -> -0.79261243 | H11: =raw!H11 -> -0.88592923 | I11: =raw!I11 -> -0.88002038 | J11: =raw!J11 -> -0.83616048 | ... U11: =raw!U11 -> -0.61042804
A12: =raw!A12 -> Egypt | B12: =raw!B12 -> 🇪🇬 | C12: =raw!C12 -> GDP per capita, PPP (constant 2021 international $) | D12: =LN( raw!D12) -> 9.224589 | E12: =LN( raw!E12) -> 9.2350697 | F12: =LN( raw!F12) -> 9.2545316 | G12: =LN( raw!G12) -> 9.2780559 | H12: =LN( raw!H12) -> 9.3247249 | I12: =LN( raw!I12) -> 9.3743287 | J12: =LN( raw!J12) -> 9.4247729 | K12: =LN( raw!K12) -> 9.451566 | ... U12: =LN( raw!U12) -> 9.6175751
A13: =raw!A13 -> Egypt | B13: =raw!B13 -> 🇪🇬 | C13: =raw!C13 -> International tourism, number of arrivals | D13: =LN(raw!D13) -> 15.46263 | E13: =LN(raw!E13) -> 15.614577 | F13: =LN(raw!F13) -> 15.907868 | G13: =LN(raw!G13) -> 15.968203 | H13: =LN(raw!H13) -> 16.021915 | I13: =LN(raw!I13) -> 16.221645 | J13: =LN(raw!J13) -> 16.367686 | K13: =LN(raw!K13) -> 16.344115 | ... U13: =LN(raw!U13) -> 16.382458
A14: =raw!A14 -> Egypt | B14: =raw!B14 -> 🇪🇬 | C14: =raw!C14 -> Political Stability and Absence of Violence/Terrorism: Estimate | D14: =raw!D14 -> -0.41417211 | E14: =raw!E14 -> -0.64092451 | F14: =raw!F14 -> -0.8224017 | G14: =raw!G14 -> -0.62935865 | H14: =raw!H14 -> -0.83780766 | ... U14: =raw!U14 -> -1.1246308
A15: =raw!A15 -> Egypt | B15: =raw!B15 -> 🇪🇬 | C15: =raw!C15 -> Official exchange rate (LCU per US$, period average) | D15: =LN(raw!D15) -> 1.5040033 | E15: =LN(raw!E15) -> 1.7665912 | F15: =LN(raw!F15) -> 1.8239429 | G15: =LN(raw!G15) -> 1.7542018 | H15: =LN(raw!H15) -> 1.746268 | I15: =LN(raw!I15) -> 1.729074 | J15: =LN(raw!J15) -> 1.6923994 | K15: =LN(raw!K15) -> 1.7128161 | ... U15: =LN(raw!U15) -> 2.8196263
A16: Egypt | B16: 🇪🇬 | C16: =raw!C16 -> Rule of Law: Estimate | D16: =raw!D16 -> -0.011468072 | E16: =raw!E16 -> -0.0023544689 | F16: =raw!F16 -> 0.013317895 | G16: =raw!G16 -> -0.0012232348 | H16: =raw!H16 -> -0.27896744 | I16: =raw!I16 -> -0.24621348 | J16: =raw!J16 -> -0.1297836 | ... U16: =raw!U16 -> -0.33212334
A17: =raw!A17 -> Georgia | B17: =raw!B17 -> 🇬🇪 | C17: =raw!C17 -> GDP per capita, PPP (constant 2021 international $) | D17: =LN(raw!D17) -> 8.7740539 | E17: =LN(raw!E17) -> 8.8856813 | F17: =LN(raw!F17) -> 8.9481851 | G17: =LN(raw!G17) -> 9.0461243 | H17: =LN(raw!H17) -> 9.1418462 | I17: =LN(raw!I17) -> 9.2655172 | J17: =LN(raw!J17) -> 9.2924827 | K17: =LN(raw!K17) -> 9.264174 | ... U17: =LN(raw!U17) -> 9.8084558
A18: =raw!A18 -> Georgia | B18: =raw!B18 -> 🇬🇪 | C18: =raw!C18 -> International tourism, number of arrivals | D18: =LN( raw!D18) -> 12.604849 | E18: =LN( raw!E18) -> 12.653958 | F18: =LN( raw!F18) -> 12.815838 | G18: =LN( raw!G18) -> 13.235692 | H18: =LN( raw!H18) -> 13.798364 | I18: =LN( raw!I18) -> 13.866204 | J18: =LN( raw!J18) -> 14.070153 | K18: =LN( raw!K18) -> 14.220976 | ... U18: =LN( raw!U18) -> 15.860102
A19: =raw!A19 -> Georgia | B19: =raw!B19 -> 🇬🇪 | C19: =raw!C19 -> Political Stability and Absence of Violence/Terrorism: Estimate | D19: =raw!D19 -> -1.1920414 | E19: =raw!E19 -> -1.2992107 | F19: =raw!F19 -> -0.86411816 | G19: =raw!G19 -> -0.75590491 | H19: =raw!H19 -> -0.96609879 | ... U19: =raw!U19 -> -0.49817196
A20: =raw!A20 -> Georgia | B20: =raw!B20 -> 🇬🇪 | C20: =raw!C20 -> Official exchange rate (LCU per US$, period average) | D20: =LN(raw!D20) -> 0.78648952 | E20: =LN(raw!E20) -> 0.76344254 | F20: =LN(raw!F20) -> 0.65057887 | G20: =LN(raw!G20) -> 0.59480365 | H20: =LN(raw!H20) -> 0.57685678 | I20: =LN(raw!I20) -> 0.51311799 | J20: =LN(raw!J20) -> 0.3993073 | K20: =LN(raw!K20) -> 0.51311526 | ... U20: =LN(raw!U20) -> 1.0360789
A21: =raw!A21 -> Georgia | B21: =raw!B21 -> 🇬🇪 | C21: =raw!C21 -> Rule of Law: Estimate | D21: =raw!D21 -> -1.0840563 | E21: =raw!E21 -> -0.9122541 | F21: =raw!F21 -> -0.74976999 | G21: =raw!G21 -> -0.69596261 | H21: =raw!H21 -> -0.46166733 | ... U21: =raw!U21 -> 0.24869154
A22: =raw!A22 -> India | B22: =raw!B22 -> 🇮🇳 | C22: =raw!C22 -> GDP per capita, PPP (constant 2021 international $) | D22: =LN(raw!D22) -> 8.0866243 | E22: =LN(raw!E22) -> 8.1449479 | F22: =LN(raw!F22) -> 8.2041595 | G22: =LN(raw!G22) -> 8.2640971 | H22: =LN(raw!H22) -> 8.325979 | I22: =LN(raw!I22) -> 8.3847346 | J22: =LN(raw!J22) -> 8.4007471 | K22: =LN(raw!K22) -> 8.4619683 | ... U22: =LN(raw!U22) -> 8.9784198
A23: =raw!A23 -> India | B23: =raw!B23 -> 🇮🇳 | C23: =raw!C23 -> International tourism, number of arrivals | D23: =LN(raw!D23) -> 14.68429 | E23: =LN(raw!E23) -> 14.818346 | F23: =LN(raw!F23) -> 15.055912 | G23: =LN(raw!G23) -> 15.181347 | H23: =LN(raw!H23) -> 15.30774 | I23: =LN(raw!I23) -> 15.441215 | J23: =LN(raw!J23) -> 15.480005 | K23: =LN(raw!K23) -> 15.457996 | ... U23: =LN(raw!U23) -> 16.701093
A24: =raw!A24 -> India | B24: =raw!B24 -> 🇮🇳 | C24: =raw!C24 -> Political Stability and Absence of Violence/Terrorism: Estimate | D24: =raw!D24 -> -1.210665 | E24: =raw!E24 -> -1.509997 | F24: =raw!F24 -> -1.2804329 | G24: =raw!G24 -> -1.0138805 | H24: =raw!H24 -> -1.0651842 | ... U24: =raw!U24 -> -0.79684699
A25: =raw!A25 -> India | B25: =raw!B25 -> 🇮🇳 | C25: =raw!C25 -> Official exchange rate (LCU per US$, period average) | D25: =LN(raw!D25) -> 3.8838358 | E25: =LN(raw!E25) -> 3.8412418 | F25: =LN(raw!F25) -> 3.8136705 | G25: =LN(raw!G25) -> 3.7864592 | H25: =LN(raw!H25) -> 3.8134617 | I25: =LN(raw!I25) -> 3.722037 | J25: =LN(raw!J25) -> 3.7728801 | K25: =LN(raw!K25) -> 3.8796086 | ... U25: =LN(raw!U25) -> 4.2544821
A26: India | B26: =raw!B26 -> 🇮🇳 | C26: =raw!C26 -> Rule of Law: Estimate | D26: =raw!D26 -> -0.017395871 | E26: =raw!E26 -> 0.12016165 | F26: =raw!F26 -> 0.053356059 | G26: =raw!G26 -> 0.13313016 | H26: =raw!H26 -> 0.17898962 | I26: =raw!I26 -> 0.096898161 | ... U26: =raw!U26 -> -0.067227155
A27: =raw!A27 -> Iran | B27: =raw!B27 -> 🇮🇷 | C27: =raw!C27 -> GDP per capita, PPP (constant 2021 international $) | D27: =LN(raw!D27) -> 9.3749133 | E27: =LN(raw!E27) -> 9.4466924 | F27: =LN(raw!F27) -> 9.4677529 | G27: =LN(raw!G27) -> 9.4770222 | H27: =LN(raw!H27) -> 9.504266 | I27: =LN(raw!I27) -> 9.5663175 | J27: =LN(raw!J27) -> 9.5566781 | K27: =LN(raw!K27) -> 9.5542831 | ... U27: =LN(raw!U27) -> 9.549713
A28: =raw!A28 -> Iran | B28: =raw!B28 -> 🇮🇷 | C28: =raw!C28 -> International tourism, number of arrivals | D28: =LN(raw!D28) -> 14.276095 | E28: =LN(raw!E28) -> 14.251182 | F28: =LN(raw!F28) -> 14.321726 | G28: =LN(raw!G28) -> 14.451558 | H28: =LN(raw!H28) -> 14.821642 | I28: =LN(raw!I28) -> 14.612567 | J28: =LN(raw!J28) -> 14.525515 | K28: =LN(raw!K28) -> 14.565038 | ... U28: =LN(raw!U28) -> 16.024554
A29: =raw!A29 -> Iran | B29: =raw!B29 -> 🇮🇷 | C29: =raw!C29 -> Political Stability and Absence of Violence/Terrorism: Estimate | D29: =raw!D29 -> -0.7734406 | E29: =raw!E29 -> -0.77973318 | F29: =raw!F29 -> -0.76182431 | G29: =raw!G29 -> -0.78273886 | H29: =raw!H29 -> -1.04084 | ... U29: =raw!U29 -> -1.711534
A30: =raw!A30 -> Iran | B30: =raw!B30 -> 🇮🇷 | C30: =raw!C30 -> Official exchange rate (LCU per US$, period average) | D30: =LN(raw!D30) -> 8.8402957 | E30: =LN(raw!E30) -> 9.0111437 | F30: =LN(raw!F30) -> 9.0611428 | G30: =LN(raw!G30) -> 9.1009673 | H30: =LN(raw!H30) -> 9.1237954 | I30: =LN(raw!I30) -> 9.1357409 | J30: =LN(raw!J30) -> 9.1514953 | K30: =LN(raw!K30) -> 9.1966777 | ... U30: =LN(raw!U30) -> 10.645425
A31: =raw!A31 -> Iran | B31: =raw!B31 -> 🇮🇷 | C31: =raw!C31 -> Rule of Law: Estimate | D31: =raw!D31 -> -0.8217777 | E31: =raw!E31 -> -0.68051577 | F31: =raw!F31 -> -0.67358148 | G31: =raw!G31 -> -0.86580431 | H31: =raw!H31 -> -0.99435616 | ... U31: =raw!U31 -> -0.77147895
A32: =raw!A32 -> Italy | B32: =raw!B32 -> 🇮🇹 | C32: =raw!C32 -> GDP per capita, PPP (constant 2021 international $) | D32: =LN(raw!D32) -> 10.847332 | E32: =LN(raw!E32) -> 10.843553 | F32: =LN(raw!F32) -> 10.851713 | G32: =LN(raw!G32) -> 10.854395 | H32: =LN(raw!H32) -> 10.869224 | I32: =LN(raw!I32) -> 10.878692 | J32: =LN(raw!J32) -> 10.861783 | K32: =LN(raw!K32) -> 10.802716 | ... U32: =LN(raw!U32) -> 10.813572
A33: =raw!A33 -> Italy | B33: =raw!B33 -> 🇮🇹 | C33: =raw!C33 -> International tourism, number of arrivals | D33: =LN(raw!D33) -> 17.967511 | E33: =LN(raw!E33) -> 17.959058 | F33: =LN(raw!F33) -> 17.884195 | G33: =LN(raw!G33) -> 17.896939 | H33: =LN(raw!H33) -> 18.0105 | I33: =LN(raw!I33) -> 18.06787 | J33: =LN(raw!J33) -> 18.074225 | K33: =LN(raw!K33) -> 18.08789 | ... U33: =LN(raw!U33) -> 18.373579
A34: =raw!A34 -> Italy | B34: =raw!B34 -> 🇮🇹 | C34: =raw!C34 -> Political Stability and Absence of Violence/Terrorism: Estimate | D34: =raw!D34 -> 0.83842981 | E34: =raw!E34 -> 0.43148834 | F34: =raw!F34 -> 0.26925769 | G34: =raw!G34 -> 0.48911554 | H34: =raw!H34 -> 0.53073376 | ... U34: =raw!U34 -> 0.38111427
A35: =raw!A35 -> Italy | B35: =raw!B35 -> 🇮🇹 | C35: =raw!C35 -> Official exchange rate (LCU per US$, period average) | D35: =LN(raw!D35) -> 0.055963419 | E35: =LN(raw!E35) -> -0.123244 | F35: =LN(raw!F35) -> -0.21825347 | G35: =LN(raw!G35) -> -0.21840456 | H35: =LN(raw!H35) -> -0.22761261 | I35: =LN(raw!I35) -> -0.31515961 | J35: =LN(raw!J35) -> -0.38577619 | K35: =LN(raw!K35) -> -0.33273843 | ... U35: =LN(raw!U35) -> -0.11285939
A36: =raw!A36 -> Italy | B36: =raw!B36 -> 🇮🇹 | C36: =raw!C36 -> Rule of Law: Estimate | D36: =raw!D36 -> 0.74014199 | E36: =raw!E36 -> 0.68842989 | F36: =raw!F36 -> 0.59000391 | G36: =raw!G36 -> 0.50924301 | H36: =raw!H36 -> 0.37900639 | ... U36: =raw!U36 -> 0.27241716
A37: =raw!A37 -> Kazakhstan | B37: =raw!B37 -> 🇰🇿 | C37: =raw!C37 -> GDP per capita, PPP (constant 2021 international $) | D37: =LN(raw!D37) -> 9.6778956 | E37: =LN(raw!E37) -> 9.7610453 | F37: =LN(raw!F37) -> 9.846207 | G37: =LN(raw!G37) -> 9.9313716 | H37: =LN(raw!H37) -> 10.024569 | I37: =LN(raw!I37) -> 10.100342 | J37: =LN(raw!J37) -> 10.122449 | K37: =LN(raw!K37) -> 10.122677 | ... U37: =LN(raw!U37) -> 10.413259
A38: =raw!A38 -> Kazakhstan | B38: =raw!B38 -> 🇰🇿 | C38: =raw!C38 -> International tourism, number of arrivals | D38: =LN(raw!D38) -> 15.11788 | E38: =LN(raw!E38) -> 14.990158 | F38: =LN(raw!F38) -> 15.27203 | G38: =LN(raw!G38) -> 15.289129 | H38: =LN(raw!H38) -> 15.364561 | I38: =LN(raw!I38) -> 15.485291 | J38: =LN(raw!J38) -> 15.230635 | K38: =LN(raw!K38) -> 15.143646 | ... U38: =LN(raw!U38) -> 15.95734
A39: =raw!A39 -> Kazakhstan | B39: =raw!B39 -> 🇰🇿 | C39: =raw!C39 -> Political Stability and Absence of Violence/Terrorism: Estimate | D39: =raw!D39 -> 0.35854918 | E39: =raw!E39 -> 0.35625991 | F39: =raw!F39 -> 0.070387974 | G39: =raw!G39 -> 0.19063184 | H39: =raw!H39 -> 0.20793781 | ... U39: =raw!U39 -> -0.16803734
A40: =raw!A40 -> Kazakhstan | B40: =raw!B40 -> 🇰🇿 | C40: =raw!C40 -> Official exchange rate (LCU per US$, period average) | D40: =LN(raw!D40) -> 5.0322609 | E40: =LN(raw!E40) -> 5.0078035 | F40: =LN(raw!F40) -> 4.9129122 | G40: =LN(raw!G40) -> 4.8894465 | H40: =LN(raw!H40) -> 4.8369914 | I40: =LN(raw!I40) -> 4.8085531 | J40: =LN(raw!J40) -> 4.7899817 | K40: =LN(raw!K40) -> 4.9938056 | ... U40: =LN(raw!U40) -> 5.947375
...

Sheet raw
A1: country | B1: country_id | C1: variable | D1: 2002 | E1: 2003 | F1: 2004 | G1: 2005 | H1: 2006 | I1: 2007 | J1: 2008 | K1: 2009 | L1: 2010 | M1: 2011 | N1: 2012 | O1: 2013 | P1: 2014 | Q1: 2015 | R1: 2016 | S1: 2017 | T1: 2018 | U1: 2019
A2: Azerbaijan | B2: 🇦🇿 | C2: GDP per capita, PPP (constant 2021 international $) | D2: 6599.6576 | E2: 7218.4719 | F2: 7817.7161 | G2: 9901.9266 | H2: 13172.581 | I2: 16280.084 | J2: 17656.963 | K2: 18901.886 | L2: 19621.384 | M2: 19386.743 | N2: 19545.072 | O2: 20414.831 | P2: 20716.142 | Q2: 20694.779 | R2: 19830.322 | S2: 19675.96 | T2: 19798.834 | U2: 20122.713
A3: Azerbaijan | B3: 🇦🇿 | C3: International tourism, number of arrivals | D3: 834000 | E3: 1038000 | F3: 1279000 | G3: 1177000 | H3: 1194000 | I3: 1333000 | J3: 1899000 | K3: 1830000 | L3: 1963000 | M3: 2239000 | N3: 2484000 | O3: 2509000 | P3: 2298000 | Q3: 2006000 | R3: 2249000 | S3: 2697000 | T3: 2850000 | U3: 3170000
A4: Azerbaijan | B4: 🇦🇿 | C4: Political Stability and Absence of Violence/Terrorism: Estimate | D4: -1.185365 | E4: -0.94810039 | F4: -1.0598111 | G4: -1.1248194 | H4: -1.0926824 | I4: -0.62599641 | J4: -0.33034998 | K4: -0.27785352 | L4: -0.23854692 | M4: -0.53213596 | N4: -0.71575183 | O4: -0.41285992 | P4: -0.55990952 | Q4: -0.73391664 | R4: -0.80890882 | S4: -0.75190103 | T4: -0.71139938 | U4: -0.69341147
A5: Azerbaijan | B5: 🇦🇿 | C5: Official exchange rate (LCU per US$, period average) | D5: 0.97216417 | E5: 0.982146 | F5: 0.9826955 | G5: 0.945421 | H5: 0.893445 | I5: 0.85812381 | J5: 0.82161958 | K5: 0.80378333 | L5: 0.80265 | M5: 0.78968639 | N5: 0.78564535 | O5: 0.78454108 | P5: 0.7843475 | Q5: 1.0245638 | R5: 1.5957216 | S5: 1.7211548 | T5: 1.7000167 | U5: 1.7
A6: ='Rule of Law'!A20 -> Azerbaijan | B6: ='Rule of Law'!B20 -> AZE | C6: ='Rule of Law'!C20 -> Rule of Law: Estimate | D6: ='Rule of Law'!AU20 -> -0.96419722 | E6: ='Rule of Law'!AV20 -> -0.88464475 | F6: ='Rule of Law'!AW20 -> -0.90051848 | G6: ='Rule of Law'!AX20 -> -0.79261243 | H6: ='Rule of Law'!AY20 -> -0.88592923 | I6: ='Rule of Law'!AZ20 -> -0.88002038 | J6: ='Rule of Law'!BA20 -> -0.83616048 | K6: ='Rule of Law'!BB20 -> -0.87917602 | ... U6: ='Rule of Law'!BL20 -> -0.61042804
A7: China | B7: 🇨🇳 | C7: GDP per capita, PPP (constant 2021 international $) | D7: 4650.8968 | E7: 5085.9778 | F7: 5567.1906 | G7: 6165.1834 | H7: 6910.7579 | I7: 7853.0964 | J7: 8566.9649 | K7: 9325.6508 | L7: 10267.806 | M7: 11187.166 | N7: 11985.317 | O7: 12830.37 | P7: 13696.517 | Q7: 14575.935 | R7: 15485.213 | S7: 16461.07 | T7: 17490.167 | U7: 18465.299
A8: China | B8: 🇨🇳 | C8: International tourism, number of arrivals | D8: 97908000 | E8: 91662000 | F8: 109038000 | G8: 120292000 | H8: 124942000 | I8: 131873000 | J8: 130027000 | K8: 126476000 | L8: 133762000 | M8: 135423000 | N8: 132405000 | O8: 129078000 | P8: 128499000 | Q8: 133820000 | R8: 141774000 | S8: 153260000 | T8: 158606000 | U8: 162538000
A9: China | B9: 🇨🇳 | C9: Political Stability and Absence of Violence/Terrorism: Estimate | D9: -0.32762718 | E9: -0.56535792 | F9: -0.39068067 | G9: -0.50175661 | H9: -0.54003012 | I9: -0.50055373 | J9: -0.49308842 | K9: -0.45178133 | L9: -0.65706068 | M9: -0.60205483 | N9: -0.53878206 | O9: -0.54378992 | P9: -0.52258402 | Q9: -0.55255967 | R9: -0.50222135 | S9: -0.2325581 | T9: -0.29857248 | U9: -0.25978068 | X9: =K8 -> 126476000
A10: China | B10: 🇨🇳 | C10: Official exchange rate (LCU per US$, period average) | D10: 8.2769575 | E10: 8.2770367 | F10: 8.2768008 | G10: 8.1943167 | H10: 7.9734383 | I10: 7.6075325 | J10: 6.948655 | K10: 6.8314161 | L10: 6.770269 | M10: 6.4614613 | N10: 6.3123328 | O10: 6.1957583 | P10: 6.1434341 | Q10: 6.2274887 | R10: 6.6444778 | S10: 6.7587551 | T10: 6.6159572 | U10: 6.908385 | X10: =LN(X9) -> 18.655563
A11: China | B11: 🇨🇳 | C11: ='Rule of Law'!C45 -> Rule of Law: Estimate | D11: ='Rule of Law'!AU20 -> -0.96419722 | E11: ='Rule of Law'!AV20 -> -0.88464475 | F11: ='Rule of Law'!AW20 -> -0.90051848 | G11: ='Rule of Law'!AX20 -> -0.79261243 | H11: ='Rule of Law'!AY20 -> -0.88592923 | I11: ='Rule of Law'!AZ20 -> -0.88002038 | J11: ='Rule of Law'!BA20 -> -0.83616048 | K11: ='Rule of Law'!BB20 -> -0.87917602 | ... U11: ='Rule of Law'!BL20 -> -0.61042804
A12: Egypt | B12: 🇪🇬 | C12: GDP per capita, PPP (constant 2021 international $) | D12: 10143.506 | E12: 10250.377 | F12: 10451.822 | G12: 10700.609 | H12: 11211.832 | I12: 11782.006 | J12: 12391.585 | K12: 12728.081 | L12: 13128.988 | M12: 13082.426 | N12: 13076.805 | O12: 13058.075 | P12: 13136.366 | Q12: 13425.912 | R12: 13727.32 | S12: 14018.361 | T12: 14488.209 | U12: 15026.568
A13: Egypt | B13: 🇪🇬 | C13: International tourism, number of arrivals | D13: 5192000 | E13: 6044000 | F13: 8104000 | G13: 8608000 | H13: 9083000 | I13: 11091000 | J13: 12835000 | K13: 12536000 | L13: 14731000 | M13: 9845000 | N13: 11532000 | O13: 9464000 | P13: 9878000 | Q13: 9328000 | R13: 5399000 | S13: 8292000 | T13: 11346000 | U13: 13026000
A14: Egypt | B14: 🇪🇬 | C14: Political Stability and Absence of Violence/Terrorism: Estimate | D14: -0.41417211 | E14: -0.64092451 | F14: -0.8224017 | G14: -0.62935865 | H14: -0.83780766 | I14: -0.55238211 | J14: -0.51043171 | K14: -0.60722709 | L14: -0.89841831 | M14: -1.437057 | N14: -1.4363297 | O14: -1.6388309 | P14: -1.6311766 | Q14: -1.4993322 | R14: -1.4397268 | S14: -1.4296459 | T14: -1.1881216 | U14: -1.1246308
A15: Egypt | B15: 🇪🇬 | C15: Official exchange rate (LCU per US$, period average) | D15: 4.4996667 | E15: 5.850875 | F15: 6.1962417 | G15: 5.7788333 | H15: 5.7331667 | I15: 5.6354333 | J15: 5.4325 | K15: 5.5445533 | L15: 5.6219429 | M15: 5.9328277 | N15: 6.0560583 | O15: 6.870325 | P15: 7.0776086 | Q15: 7.6912583 | R15: 10.025401 | S15: 17.782534 | T15: 17.76729 | U15: 16.770582
A16: Egypt | B16: 🇪🇬 | C16: ='Rule of Law'!C72 -> Rule of Law: Estimate | D16: ='Rule of Law'!AU72 -> -0.011468072 | E16: ='Rule of Law'!AV72 -> -0.0023544689 | F16: ='Rule of Law'!AW72 -> 0.013317895 | G16: ='Rule of Law'!AX72 -> -0.0012232348 | H16: ='Rule of Law'!AY72 -> -0.27896744 | I16: ='Rule of Law'!AZ72 -> -0.24621348 | J16: ='Rule of Law'!BA72 -> -0.1297836 | K16: ='Rule of Law'!BB72 -> -0.083344996 | ... U16: ='Rule of Law'!BL72 -> -0.33212334
A17: Georgia | B17: 🇬🇪 | C17: GDP per capita, PPP (constant 2021 international $) | D17: 6464.3254 | E17: 7227.7371 | F17: 7693.9153 | G17: 8485.5867 | H17: 9337.9891 | I17: 10567.275 | J17: 10856.103 | K17: 10553.09 | L17: 11294.369 | M17: 12288.683 | N17: 13193.96 | O17: 13913.002 | P17: 14475.314 | Q17: 14936.843 | R17: 15442.956 | S17: 16237.624 | T17: 17228.679 | U17: 18186.882
A18: Georgia | B18: 🇬🇪 | C18: International tourism, number of arrivals | D18: 298000 | E18: 313000 | F18: 368000 | G18: 560000 | H18: 983000 | I18: 1052000 | J18: 1290000 | K18: 1500000 | L18: 2032000 | M18: 2712000 | N18: 4106000 | O18: 4954000 | P18: 5004000 | Q18: 5256000 | R18: 5393000 | S18: 6483000 | T18: 7203000 | U18: 7726000
A19: Georgia | B19: 🇬🇪 | C19: Political Stability and Absence of Violence/Terrorism: Estimate | D19: -1.1920414 | E19: -1.2992107 | F19: -0.86411816 | G19: -0.75590491 | H19: -0.96609879 | I19: -0.645899 | J19: -0.91967511 | K19: -0.96552491 | L19: -0.71832091 | M19: -0.65695196 | N19: -0.68045396 | O19: -0.44136617 | P19: -0.32150754 | Q19: -0.47215375 | R19: -0.32011509 | S19: -0.37521476 | T19: -0.44756287 | U19: -0.49817196
A20: Georgia | B20: 🇬🇪 | C20: Official exchange rate (LCU per US$, period average) | D20: 2.195675 | E20: 2.14565 | F20: 1.91665 | G20: 1.812675 | H20: 1.7804333 | I20: 1.6704917 | J20: 1.4907917 | K20: 1.6704871 | L20: 1.7823417 | M20: 1.6864954 | N20: 1.6512583 | O20: 1.66335 | P20: 1.7656667 | Q20: 2.2693417 | R20: 2.366725 | S20: 2.5095417 | T20: 2.5341108 | U20: 2.818145
A21: ='Rule of Law'!A87 -> Georgia | B21: 🇬🇪 | C21: ='Rule of Law'!C87 -> Rule of Law: Estimate | D21: ='Rule of Law'!AU87 -> -1.0840563 | E21: ='Rule of Law'!AV87 -> -0.9122541 | F21: ='Rule of Law'!AW87 -> -0.74976999 | G21: ='Rule of Law'!AX87 -> -0.69596261 | H21: ='Rule of Law'!AY87 -> -0.46166733 | I21: ='Rule of Law'!AZ87 -> -0.34445915 | J21: ='Rule of Law'!BA87 -> -0.26294446 | K21: ='Rule of Law'!BB87 -> -0.19931532 | ... U21: ='Rule of Law'!BL87 -> 0.24869154
A22: India | B22: 🇮🇳 | C22: GDP per capita, PPP (constant 2021 international $) | D22: 3250.6957 | E22: 3445.9259 | F22: 3656.1262 | G22: 3881.9662 | H22: 4129.7784 | I22: 4379.696 | J22: 4450.3902 | K22: 4731.3616 | L22: 5059.2827 | M22: 5249.5493 | N22: 5460.4377 | O22: 5732.2419 | P22: 6079.8439 | Q22: 6488.146 | R22: 6940.6259 | S22: 7326.6069 | T22: 7714.3397 | U22: 7930.0911
A23: India | B23: 🇮🇳 | C23: International tourism, number of arrivals | D23: 2384000 | E23: 2726000 | F23: 3457000 | G23: 3919000 | H23: 4447000 | I23: 5082000 | J23: 5283000 | K23: 5168000 | L23: 5776000 | M23: 6309000 | N23: 6578000 | O23: 6968000 | P23: 13107000 | Q23: 13284000 | R23: 14570000 | S23: 15543000 | T23: 17423000 | U23: 17914000
A24: India | B24: 🇮🇳 | C24: Political Stability and Absence of Violence/Terrorism: Estimate | D24: -1.210665 | E24: -1.509997 | F24: -1.2804329 | G24: -1.0138805 | H24: -1.0651842 | I24: -1.1542958 | J24: -1.1097074 | K24: -1.3555479 | L24: -1.2779845 | M24: -1.3267953 | N24: -1.2893099 | O24: -1.2291741 | P24: -0.99791199 | Q24: -0.95477355 | R24: -0.96042651 | S24: -0.77409911 | T24: -0.99770677 | U24: -0.79684699
A25: India | B25: 🇮🇳 | C25: Official exchange rate (LCU per US$, period average) | D25: 48.610319 | E25: 46.583284 | F25: 45.316467 | G25: 44.099975 | H25: 45.307008 | I25: 41.348533 | J25: 43.505183 | K25: 48.405267 | L25: 45.725812 | M25: 46.670467 | N25: 53.437233 | O25: 58.597845 | P25: 61.029514 | Q25: 64.151944 | R25: 67.195313 | S25: 65.121569 | T25: 68.389467 | U25: 70.420341
A26: =#REF! -> #REF! | B26: 🇮🇳 | C26: ='Rule of Law'!C114 -> Rule of Law: Estimate | D26: ='Rule of Law'!AU114 -> -0.017395871 | E26: ='Rule of Law'!AV114 -> 0.12016165 | F26: ='Rule of Law'!AW114 -> 0.053356059 | G26: ='Rule of Law'!AX114 -> 0.13313016 | H26: ='Rule of Law'!AY114 -> 0.17898962 | I26: ='Rule of Law'!AZ114 -> 0.096898161 | J26: ='Rule of Law'!BA114 -> 0.09585046 | K26: ='Rule of Law'!BB114 -> 0.017980825 | ... U26: ='Rule of Law'!BL114 -> -0.067227155
A27: Iran | B27: 🇮🇷 | C27: GDP per capita, PPP (constant 2021 international $) | D27: 11788.895 | E27: 12666.201 | F27: 12935.786 | G27: 13056.25 | H27: 13416.842 | I27: 14275.749 | J27: 14138.801 | K27: 14104.978 | L27: 14737.156 | M27: 14941.259 | N27: 14202.551 | O27: 13804.791 | P27: 14299.572 | Q27: 13905.192 | R27: 14915.594 | S27: 15108.109 | T27: 14642.498 | U27: 14040.665
A28: Iran | B28: 🇮🇷 | C28: International tourism, number of arrivals | D28: 1585000 | E28: 1546000 | F28: 1659000 | G28: 1889000 | H28: 2735000 | I28: 2219000 | J28: 2034000 | K28: 2116000 | L28: 2938000 | M28: 3354000 | N28: 3834000 | O28: 4769000 | P28: 4968000 | Q28: 5237000 | R28: 4942000 | S28: 4867000 | T28: 7295000 | U28: 9107000
A29: Iran | B29: 🇮🇷 | C29: Political Stability and Absence of Violence/Terrorism: Estimate | D29: -0.7734406 | E29: -0.77973318 | F29: -0.76182431 | G29: -0.78273886 | H29: -1.04084 | I29: -0.93164045 | J29: -0.93987471 | K29: -1.564242 | L29: -1.6305919 | M29: -1.4217677 | N29: -1.3239261 | O29: -1.2496866 | P29: -0.87498766 | Q29: -0.92484689 | R29: -0.81402063 | S29: -0.93382889 | T29: -1.3421807 | U29: -1.711534
A30: Iran | B30: 🇮🇷 | C30: Official exchange rate (LCU per US$, period average) | D30: 6907.0345 | E30: 8193.8875 | F30: 8613.9894 | G30: 8963.9589 | H30: 9170.9429 | I30: 9281.1518 | J30: 9428.5283 | K30: 9864.3025 | L30: 10254.176 | M30: 10616.307 | N30: 12175.547 | O30: 18414.448 | P30: 25941.664 | Q30: 29011.491 | R30: 30914.852 | S30: 33226.298 | T30: 40864.329 | U30: 42000
A31: Iran | B31: 🇮🇷 | C31: ='Rule of Law'!C117 -> Rule of Law: Estimate | D31: ='Rule of Law'!AU117 -> -0.8217777 | E31: ='Rule of Law'!AV117 -> -0.68051577 | F31: ='Rule of Law'!AW117 -> -0.67358148 | G31: ='Rule of Law'!AX117 -> -0.86580431 | H31: ='Rule of Law'!AY117 -> -0.99435616 | I31: ='Rule of Law'!AZ117 -> -1.0274519 | J31: ='Rule of Law'!BA117 -> -0.97846395 | K31: ='Rule of Law'!BB117 -> -1.0536784 | ... U31: ='Rule of Law'!BL117 -> -0.77147895
A32: Italy | B32: 🇮🇹 | C32: GDP per capita, PPP (constant 2021 international $) | D32: 51396.859 | E32: 51202.958 | F32: 51622.525 | G32: 51761.126 | H32: 52534.423 | I32: 53034.165 | J32: 52144.961 | K32: 49154.126 | L32: 49752.475 | M32: 50012.401 | N32: 48318.979 | O32: 46893.748 | P32: 46464.819 | Q32: 46921.542 | R32: 47582.362 | S32: 48417.946 | T32: 48911.065 | U32: 49690.63
A33: Italy | B33: 🇮🇹 | C33: International tourism, number of arrivals | D33: 63561000 | E33: 63026000 | F33: 58480000 | G33: 59230000 | H33: 66353000 | I33: 70271000 | J33: 70719000 | K33: 71692000 | L33: 73225000 | M33: 75866000 | N33: 76293000 | O33: 76762000 | P33: 77694000 | Q33: 81068000 | R33: 84925000 | S33: 89931000 | T33: 93228602 | U33: 95399000
A34: Italy | B34: 🇮🇹 | C34: Political Stability and Absence of Violence/Terrorism: Estimate | D34: 0.83842981 | E34: 0.43148834 | F34: 0.26925769 | G34: 0.48911554 | H34: 0.53073376 | I34: 0.44697005 | J34: 0.54754424 | K34: 0.34690589 | L34: 0.47392368 | M34: 0.50120741 | N34: 0.50821751 | O34: 0.49549919 | P34: 0.45816541 | Q34: 0.3632572 | R34: 0.35593343 | S34: 0.29291049 | T34: 0.32627168 | U34: 0.38111427
A35: Italy | B35: 🇮🇹 | C35: Official exchange rate (LCU per US$, period average) | D35: 1.057559 | E35: 0.88404793 | F35: 0.80392165 | G35: 0.80380019 | H35: 0.79643273 | I35: 0.7296724 | J35: 0.67992268 | K35: 0.7169577 | L35: 0.75430899 | M35: 0.7184139 | N35: 0.77833812 | O35: 0.75294512 | P35: 0.7527282 | Q35: 0.90129642 | R35: 0.90342144 | S35: 0.88520551 | T35: 0.84677267 | U35: 0.89327626
A36: Italy | B36: 🇮🇹 | C36: ='Rule of Law'!C121 -> Rule of Law: Estimate | D36: ='Rule of Law'!AU121 -> 0.74014199 | E36: ='Rule of Law'!AV121 -> 0.68842989 | F36: ='Rule of Law'!AW121 -> 0.59000391 | G36: ='Rule of Law'!AX121 -> 0.50924301 | H36: ='Rule of Law'!AY121 -> 0.37900639 | I36: ='Rule of Law'!AZ121 -> 0.46754819 | J36: ='Rule of Law'!BA121 -> 0.44792145 | K36: ='Rule of Law'!BB121 -> 0.39914548 | ... U36: ='Rule of Law'!BL121 -> 0.27241716
A37: Kazakhstan | B37: 🇰🇿 | C37: GDP per capita, PPP (constant 2021 international $) | D37: 15960.874 | E37: 17344.753 | F37: 18886.581 | G37: 20565.529 | H37: 22574.343 | I37: 24351.346 | J37: 24895.665 | K37: 24901.353 | L37: 26374.841 | M37: 27946.16 | N37: 28881.242 | O37: 30177.489 | P37: 30986.438 | Q37: 30893.759 | R37: 30758.323 | S37: 31524.442 | T37: 32330.227 | U37: 33298.212
A38: Kazakhstan | B38: 🇰🇿 | C38: International tourism, number of arrivals | D38: 3678000 | E38: 3237000 | F38: 4291000 | G38: 4365000 | H38: 4707000 | I38: 5311000 | J38: 4117000 | K38: 3774000 | L38: 4097000 | M38: 5685000 | N38: 6163000 | O38: 6841000 | P38: 6333000 | Q38: 6430000 | R38: 6509000 | S38: 7701000 | T38: 8789000 | U38: 8515000
A39: Kazakhstan | B39: 🇰🇿 | C39: Political Stability and Absence of Violence/Terrorism: Estimate | D39: 0.35854918 | E39: 0.35625991 | F39: 0.070387974 | G39: 0.19063184 | H39: 0.20793781 | I39: 0.64799678 | J39: 0.62663847 | K39: 0.77681625 | L39: 0.52297181 | M39: -0.33857056 | N39: -0.40845501 | O39: -0.4024739 | P39: 0.036018156 | Q39: -0.038353074 | R39: 0.0014629734 | S39: 0.02434968 | T39: -0.052402258 | U39: -0.16803734
A40: Kazakhstan | B40: 🇰🇿 | C40: Official exchange rate (LCU per US$, period average) | D40: 153.27917 | E40: 149.57583 | F40: 136.035 | G40: 132.88 | H40: 126.08943 | I40: 122.55417 | J40: 120.29917 | K40: 147.49667 | L40: 147.355 | M40: 146.62083 | N40: 149.1125 | O40: 152.12917 | P40: 179.19167 | Q40: 221.72833 | R40: 342.16 | S40: 326.00102 | T40: 344.70583 | U40: 382.74731
...

Sheet Rule of Law
A1: Data Source | B1: World Development Indicators
A2: Last Updated Date | B2: 45813
A4: Country Name | B4: Country Code | C4: Indicator Name | D4: Indicator Code | E4: 1960 | F4: 1961 | G4: 1962 | H4: 1963 | I4: 1964 | J4: 1965 | K4: 1966 | L4: 1967 | M4: 1968 | N4: 1969 | O4: 1970 | P4: 1971 | Q4: 1972 | R4: 1973 | S4: 1974 | T4: 1975 | U4: 1976 | V4: 1977 | W4: 1978 | X4: 1979 | Y4: 1980 | Z4: 1981 | AA4: 1982 | AB4: 1983 | AC4: 1984 | AD4: 1985 | AE4: 1986 | AF4: 1987 | AG4: 1988 | AH4: 1989 | AI4: 1990 | AJ4: 1991 | AK4: 1992 | AL4: 1993 | AM4: 1994 | AN4: 1995 | AO4: 1996 | AP4: 1997 | AQ4: 1998 | AR4: 1999 | AS4: 2000 | AT4: 2001 | AU4: 2002 | AV4: 2003 | AW4: 2004 | AX4: 2005 | AY4: 2006 | AZ4: 2007 | BA4: 2008 | BB4: 2009 | BC4: 2010 | BD4: 2011 | BE4: 2012 | BF4: 2013 | BG4: 2014 | BH4: 2015 | BI4: 2016 | BJ4: 2017 | BK4: 2018 | BL4: 2019 | BM4: 2020 | BN4: 2021 | BO4: 2022 | BP4: 2023 | BQ4: 2024
A5: Aruba | B5: ABW | C5: Rule of Law: Estimate | D5: RL.EST | AW5: 0.91552681 | AX5: 0.8474384 | AY5: 0.8104313 | AZ5: 0.82646406 | BA5: 0.84722614 | BB5: 1.4262067 | BC5: 1.4161136 | BD5: 1.3224584 | BE5: 1.3097883 | BF5: 1.2926332 | BG5: 1.0364249 | BH5: 1.2271379 | BI5: 1.2266481 | BJ5: 1.2958426 | BK5: 1.259654 | BL5: 1.228346 | BM5: 1.2705996 | BN5: 1.2466658 | BO5: 1.2780261 | BP5: 1.2702068
A6: Africa Eastern and Southern | B6: AFE | C6: Rule of Law: Estimate | D6: RL.EST
A7: Afghanistan | B7: AFG | C7: Rule of Law: Estimate | D7: RL.EST | AO7: -1.7880754 | AQ7: -1.7348868 | AS7: -1.7806607 | AU7: -1.6734732 | AV7: -1.5582937 | AW7: -1.6939253 | AX7: -1.6629655 | AY7: -1.8790048 | AZ7: -1.85256 | BA7: -1.9033076 | BB7: -1.8761188 | BC7: -1.8700581 | BD7: -1.9225001 | BE7: -1.6518931 | BF7: -1.6097552 | BG7: -1.4377019 | BH7: -1.5162007 | BI7: -1.5225337 | BJ7: -1.5811764 | BK7: -1.6891239 | BL7: -1.7421005 | BM7: -1.8314067 | BN7: -1.877234 | BO7: -1.6598456 | BP7: -1.6496409
A8: Africa Western and Central | B8: AFW | C8: Rule of Law: Estimate | D8: RL.EST
A9: Angola | B9: AGO | C9: Rule of Law: Estimate | D9: RL.EST | AO9: -1.6304693 | AQ9: -1.5273386 | AS9: -1.6015017 | AU9: -1.6333438 | AV9: -1.4828559 | AW9: -1.5209163 | AX9: -1.464795 | AY9: -1.3112727 | AZ9: -1.3751335 | BA9: -1.3785639 | BB9: -1.2362893 | BC9: -1.2729533 | BD9: -1.2770532 | BE9: -1.3047769 | BF9: -1.2909478 | BG9: -1.074954 | BH9: -1.0306587 | BI9: -1.0039502 | BJ9: -1.0399821 | BK9: -1.001062 | BL9: -1.0235482 | BM9: -0.9510588 | BN9: -0.98375362 | BO9: -1.0220357 | BP9: -1.099066
A10: Albania | B10: ALB | C10: Rule of Law: Estimate | D10: RL.EST | AO10: -0.6844818 | AQ10: -0.9296717 | AS10: -1.0206677 | AU10: -0.76232141 | AV10: -0.71632349 | AW10: -0.70103234 | AX10: -0.76383317 | AY10: -0.70313585 | AZ10: -0.66154599 | BA10: -0.6000793 | BB10: -0.49437016 | BC10: -0.38576049 | BD10: -0.44292647 | BE10: -0.51983976 | BF10: -0.51882887 | BG10: -0.3111991 | BH10: -0.3196868 | BI10: -0.32263198 | BJ10: -0.41419157 | BK10: -0.41475204 | BL10: -0.42631736 | BM10: -0.37802821 | BN10: -0.28071627 | BO10: -0.1655851 | BP10: -0.16409737
A11: Andorra | B11: AND | C11: Rule of Law: Estimate | D11: RL.EST | AO11: 1.1583625 | AQ11: 1.177254 | AS11: 1.2861655 | AU11: 1.2238406 | AV11: 1.0559833 | AW11: 1.1943245 | AX11: 0.96619427 | AY11: 0.85568583 | AZ11: 1.1682451 | BA11: 1.1863877 | BB11: 1.2177851 | BC11: 1.1979246 | BD11: 1.3992738 | BE11: 1.4011878 | BF11: 1.4016154 | BG11: 1.6386052 | BH11: 1.5131918 | BI11: 1.5129361 | BJ11: 1.5355688 | BK11: 1.536508 | BL11: 1.5102149 | BM11: 1.6151816 | BN11: 1.6420512 | BO11: 1.4854831 | BP11: 1.4768989
A12: Arab World | B12: ARB | C12: Rule of Law: Estimate | D12: RL.EST
A13: United Arab Emirates | B13: ARE | C13: Rule of Law: Estimate | D13: RL.EST | AO13: 0.68841398 | AQ13: 0.71609294 | AS13: 0.6557529 | AU13: 0.7027033 | AV13: 0.5448063 | AW13: 0.43326232 | AX13: 0.38957578 | AY13: 0.31153592 | AZ13: 0.27476609 | BA13: 0.41722 | BB13: 0.39927873 | BC13: 0.31741413 | BD13: 0.49854711 | BE13: 0.53435963 | BF13: 0.61342847 | BG13: 0.65100247 | BH13: 0.61416161 | BI13: 0.81903797 | BJ13: 0.76833498 | BK13: 0.77424514 | BL13: 0.80827749 | BM13: 0.87513596 | BN13: 0.79896832 | BO13: 0.83605653 | BP13: 0.88190013
A14: Argentina | B14: ARG | C14: Rule of Law: Estimate | D14: RL.EST | AO14: 0.075552642 | AQ14: -0.038881578 | AS14: -0.21440449 | AU14: -0.76109809 | AV14: -0.77711582 | AW14: -0.76738018 | AX14: -0.55799109 | AY14: -0.57701564 | AZ14: -0.60147226 | BA14: -0.69973165 | BB14: -0.69446808 | BC14: -0.59809422 | BD14: -0.56312329 | BE14: -0.62303424 | BF14: -0.65632862 | BG14: -0.86662734 | BH14: -0.74863589 | BI14: -0.32015952 | BJ14: -0.23731203 | BK14: -0.21933043 | BL14: -0.42736045 | BM14: -0.48626596 | BN14: -0.47794789 | BO14: -0.48235181 | BP14: -0.41082653
A15: Armenia | B15: ARM | C15: Rule of Law: Estimate | D15: RL.EST | AO15: -0.46909851 | AQ15: -0.38085678 | AS15: -0.50101626 | AU15: -0.43853137 | AV15: -0.30286464 | AW15: -0.48195061 | AX15: -0.38877675 | AY15: -0.54456735 | AZ15: -0.49651805 | BA15: -0.33775136 | BB15: -0.46871069 | BC15: -0.48135832 | BD15: -0.43770641 | BE15: -0.41828197 | BF15: -0.34088895 | BG15: -0.41772676 | BH15: -0.46255133 | BI15: -0.1608945 | BJ15: -0.20939392 | BK15: -0.19721437 | BL15: -0.17746451 | BM15: -0.12583143 | BN15: -0.11983846 | BO15: -0.1695158 | BP15: -0.12201798
A16: American Samoa | B16: ASM | C16: Rule of Law: Estimate | D16: RL.EST | AW16: 0.83959645 | AX16: 1.1094154 | AY16: 1.0692215 | AZ16: 1.0909199 | BA16: 1.1179795 | BB16: 1.1250547 | BC16: 1.1112082 | BD16: 1.0909524 | BE16: 1.0963672 | BF16: 1.1014383 | BG16: 1.4073129 | BH16: 1.2855278 | BI16: 1.2791582 | BJ16: 1.2953012 | BK16: 1.2965962 | BL16: 1.2682017 | BM16: 1.1184881 | BN16: 1.13876 | BO16: 1.2211159 | BP16: 1.2124912
A17: Antigua and Barbuda | B17: ATG | C17: Rule of Law: Estimate | D17: RL.EST | AO17: 1.0508449 | AQ17: 1.0535631 | AS17: 1.0349035 | AU17: 1.0345522 | AV17: 1.0379497 | AW17: 0.90843374 | AX17: 0.65924424 | AY17: 0.92121184 | AZ17: 0.89350319 | BA17: 0.93793941 | BB17: 0.97266746 | BC17: 0.95286989 | BD17: 0.94209474 | BE17: 0.945719 | BF17: 0.83178681 | BG17: -0.1757842 | BH17: 0.55307686 | BI17: 0.47271642 | BJ17: 0.40701899 | BK17: 0.37643349 | BL17: 0.36351562 | BM17: 0.40738115 | BN17: 0.30315053 | BO17: 0.39078712 | BP17: 0.37859318
A18: Australia | B18: AUS | C18: Rule of Law: Estimate | D18: RL.EST | AO18: 1.7133991 | AQ18: 1.7568028 | AS18: 1.7220669 | AU18: 1.7670466 | AV18: 1.8427721 | AW18: 1.7953924 | AX18: 1.7128024 | AY18: 1.7567385 | AZ18: 1.7438874 | BA18: 1.7590835 | BB18: 1.7330087 | BC18: 1.7577183 | BD18: 1.7331537 | BE18: 1.7597796 | BF18: 1.7701008 | BG18: 1.9186308 | BH18: 1.7903206 | BI18: 1.7166656 | BJ18: 1.6459577 | BK18: 1.6746656 | BL18: 1.694617 | BM18: 1.6150036 | BN18: 1.6385597 | BO18: 1.5088187 | BP18: 1.5231839
A19: Austria | B19: AUT | C19: Rule of Law: Estimate | D19: RL.EST | AO19: 1.808153 | AQ19: 1.803288 | AS19: 1.8123326 | AU19: 1.8579127 | AV19: 1.8479174 | AW19: 1.8166643 | AX19: 1.8472495 | AY19: 1.8997688 | AZ19: 1.9418256 | BA19: 1.9106989 | BB19: 1.7774427 | BC19: 1.8012027 | BD19: 1.7989631 | BE19: 1.8571237 | BF19: 1.8340906 | BG19: 1.9384362 | BH19: 1.8147753 | BI19: 1.7614619 | BJ19: 1.8003546 | BK19: 1.8534831 | BL19: 1.8622981 | BM19: 1.7706089 | BN19: 1.7517545 | BO19: 1.7042732 | BP19: 1.7465655
A20: Azerbaijan | B20: AZE | C20: Rule of Law: Estimate | D20: RL.EST | AO20: -1.2011615 | AQ20: -1.1216106 | AS20: -1.1456362 | AU20: -0.96419722 | AV20: -0.88464475 | AW20: -0.90051848 | AX20: -0.79261243 | AY20: -0.88592923 | AZ20: -0.88002038 | BA20: -0.83616048 | BB20: -0.87917602 | BC20: -0.89114505 | BD20: -0.93872648 | BE20: -0.87953269 | BF20: -0.75626069 | BG20: -0.69701201 | BH20: -0.71654457 | BI20: -0.53935629 | BJ20: -0.58492249 | BK20: -0.61980081 | BL20: -0.61042804 | BM20: -0.72964275 | BN20: -0.60676503 | BO20: -0.62555218 | BP20: -0.56658608
A21: Burundi | B21: BDI | C21: Rule of Law: Estimate | D21: RL.EST | AO21: -1.4161203 | AQ21: -1.3787856 | AS21: -1.5685171 | AU21: -1.398002 | AV21: -1.4840301 | AW21: -1.4799505 | AX21: -1.1284667 | AY21: -0.98323828 | AZ21: -1.0786669 | BA21: -1.0381 | BB21: -1.1599354 | BC21: -1.2054011 | BD21: -1.1538043 | BE21: -1.0839298 | BF21: -1.0766332 | BG21: -0.97056687 | BH21: -1.1858997 | BI21: -1.4843937 | BJ21: -1.4110038 | BK21: -1.5138199 | BL21: -1.4536273 | BM21: -1.3406509 | BN21: -1.3125911 | BO21: -1.2765462 | BP21: -1.2510563
A22: Belgium | B22: BEL | C22: Rule of Law: Estimate | D22: RL.EST | AO22: 1.3669467 | AQ22: 1.2182056 | AS22: 1.3139341 | AU22: 1.3449357 | AV22: 1.3310965 | AW22: 1.3112298 | AX22: 1.2576408 | AY22: 1.2245996 | AZ22: 1.3153872 | BA22: 1.3352058 | BB22: 1.3771482 | BC22: 1.4178525 | BD22: 1.4348489 | BE22: 1.4488096 | BF22: 1.4567661 | BG22: 1.5485169 | BH22: 1.4562256 | BI22: 1.3938035 | BJ22: 1.3206259 | BK22: 1.3385925 | BL22: 1.3361577 | BM22: 1.327594 | BN22: 1.2917758 | BO22: 1.3482308 | BP22: 1.2953749
A23: Benin | B23: BEN | C23: Rule of Law: Estimate | D23: RL.EST | AO23: 0.052315507 | AQ23: 0.050550632 | AS23: -0.18152373 | AU23: -0.26057857 | AV23: -0.42570603 | AW23: -0.47660157 | AX23: -0.53401977 | AY23: -0.53156978 | AZ23: -0.51314515 | BA23: -0.53070307 | BB23: -0.65431422 | BC23: -0.67368591 | BD23: -0.65894508 | BE23: -0.57493627 | BF23: -0.56817883 | BG23: -0.48557428 | BH23: -0.55559248 | BI23: -0.62707704 | BJ23: -0.64550292 | BK23: -0.69226176 | BL23: -0.67548412 | BM23: -0.7669186 | BN23: -0.62695688 | BO23: -0.59610939 | BP23: -0.50570965
A24: Burkina Faso | B24: BFA | C24: Rule of Law: Estimate | D24: RL.EST | AO24: -0.93322164 | AQ24: -0.91285926 | AS24: -0.73238409 | AU24: -0.79984856 | AV24: -0.62417758 | AW24: -0.53574342 | AX24: -0.50052112 | AY24: -0.43382347 | AZ24: -0.39582595 | BA24: -0.34468153 | BB24: -0.20417246 | BC24: -0.19490506 | BD24: -0.3503989 | BE24: -0.4258551 | BF24: -0.52672994 | BG24: -0.54577076 | BH24: -0.54112864 | BI24: -0.4552983 | BJ24: -0.41496333 | BK24: -0.45925754 | BL24: -0.46383378 | BM24: -0.46871859 | BN24: -0.46313876 | BO24: -0.61193377 | BP24: -0.74177897
A25: Bangladesh | B25: BGD | C25: Rule of Law: Estimate | D25: RL.EST | AO25: -0.93402374 | AQ25: -0.93586451 | AS25: -0.99112999 | AU25: -0.99160123 | AV25: -1.1519439 | AW25: -1.1224821 | AX25: -0.97855186 | AY25: -0.90756404 | AZ25: -0.82715595 | BA25: -0.75237358 | BB25: -0.78457147 | BC25: -0.80101329 | BD25: -0.73333555 | BE25: -0.93616736 | BF25: -0.87157989 | BG25: -0.7823568 | BH25: -0.76960534 | BI25: -0.66950053 | BJ25: -0.67966032 | BK25: -0.64921671 | BL25: -0.643475 | BM25: -0.56553119 | BN25: -0.62569398 | BO25: -0.60169011 | BP25: -0.50265723
A26: Bulgaria | B26: BGR | C26: Rule of Law: Estimate | D26: RL.EST | AO26: -0.34495801 | AQ26: -0.22211449 | AS26: -0.12377708 | AU26: -0.056049991 | AV26: -0.17199177 | AW26: -0.11816777 | AX26: -0.10855762 | AY26: -0.10884617 | AZ26: -0.057684425 | BA26: -0.12108802 | BB26: -0.040312354 | BC26: -0.097061358 | BD26: -0.14156416 | BE26: -0.11505136 | BF26: -0.14725563 | BG26: -0.082029149 | BH26: -0.15949355 | BI26: -0.1404438 | BJ26: -0.12496056 | BK26: -0.10584983 | BL26: -0.037413392 | BM26: -0.12767299 | BN26: -0.068868451 | BO26: -0.10792271 | BP26: -0.0068576806
A27: Bahrain | B27: BHR | C27: Rule of Law: Estimate | D27: RL.EST | AO27: -0.010116266 | AQ27: 0.35234648 | AS27: 0.28027964 | AU27: 0.5455026 | AV27: 0.59370875 | AW27: 0.69661766 | AX27: 0.59705591 | AY27: 0.37095192 | AZ27: 0.52136987 | BA27: 0.52541184 | BB27: 0.51149267 | BC27: 0.42974022 | BD27: 0.34645239 | BE27: 0.25365016 | BF27: 0.32632655 | BG27: 0.41311604 | BH27: 0.40028071 | BI27: 0.43052757 | BJ27: 0.41961557 | BK27: 0.38408354 | BL27: 0.46402249 | BM27: 0.45458642 | BN27: 0.44151598 | BO27: 0.43830931 | BP27: 0.46877044
A28: Bahamas, The | B28: BHS | C28: Rule of Law: Estimate | D28: RL.EST | AO28: 1.1463612 | AQ28: 1.2585611 | AS28: 1.2908224 | AU28: 1.4009811 | AV28: 1.418728 | AW28: 1.3821536 | AX28: 1.3669137 | AY28: 1.0757134 | AZ28: 1.2513477 | BA28: 1.1856661 | BB28: 0.7905696 | BC28: 0.71639043 | BD28: 0.61066407 | BE28: 0.61443955 | BF28: 0.63205945 | BG28: 0.66378039 | BH28: 0.56819463 | BI28: 0.23302156 | BJ28: 0.16233373 | BK28: 0.068974435 | BL28: 0.045315821 | BM28: 0.021098349 | BN28: 0.070665114 | BO28: 0.13454036 | BP28: 0.17956653
... A40: Canada | B40: CAN | C40: Rule of Law: Estimate | D40: RL.EST | AO40: 1.6472547 | AQ40: 1.7149954 | AS40: 1.6654861 | AU40: 1.661396 | AV40: 1.6970565 | AW40: 1.6871473 | AX40: 1.6501472 | AY40: 1.8010833 | AZ40: 1.7971002 | BA40: 1.796393 | BB40: 1.7967267 | BC40: 1.7985904 | BD40: 1.7271199 | BE40: 1.7564212 | BF40: 1.7475076 | BG40: 1.8862972 | BH40: 1.8071414 | BI40: 1.8009148 | BJ40: 1.7634393 | BK40: 1.7151417 | BL40: 1.7197762 | BM40: 1.6191033 | BN40: 1.5928903 | BO40: 1.5646201 | BP40: 1.4730057
A41: Central Europe and the Baltics | B41: CEB | C41: Rule of Law: Estimate | D41: RL.EST
A42: Switzerland | B42: CHE | C42: Rule of Law: Estimate | D42: RL.EST | AO42: 1.9315519 | AQ42: 1.9275484 | AS42: 1.9458206 | AU42: 1.9182134 | AV42: 1.8993979 | AW42: 1.8861954 | AX42: 1.9016694 | AY42: 1.8037716 | AZ42: 1.8279457 | BA42: 1.8047079 | BB42: 1.7431409 | BC42: 1.749795 | BD42: 1.722142 | BE42: 1.811802 | BF42: 1.7960459 | BG42: 1.9902573 | BH42: 1.909281 | BI42: 1.9061629 | BJ42: 1.888672 | BK42: 1.88756 | BL42: 1.8626593 | BM42: 1.7768903 | BN42: 1.7679853 | BO42: 1.7511884 | BP42: 1.7617257
A43: Channel Islands | B43: CHI | C43: Rule of Law: Estimate | D43: RL.EST
A44: Chile | B44: CHL | C44: Rule of Law: Estimate | D44: RL.EST | AO44: 1.1137382 | AQ44: 1.0976018 | AS44: 1.2609234 | AU44: 1.2572401 | AV44: 1.1772108 | AW44: 1.1656967 | AX44: 1.210211 | AY44: 1.1812912 | AZ44: 1.1951876 | BA44: 1.2103573 | BB44: 1.1940905 | BC44: 1.2254157 | BD44: 1.2633386 | BE44: 1.2876568 | BF44: 1.2551378 | BG44: 1.3487036 | BH44: 1.2197291 | BI44: 0.96039355 | BJ44: 0.98147547 | BK44: 0.94026053 | BL44: 0.92421663 | BM44: 0.93016213 | BN44: 0.88989067 | BO44: 0.68845445 | BP44: 0.62509376
A45: China | B45: CHN | C45: Rule of Law: Estimate | D45: RL.EST | AO45: -0.54558998 | AQ45: -0.47680536 | AS45: -0.51611716 | AU45: -0.51702976 | AV45: -0.55304384 | AW45: -0.58546871 | AX45: -0.65017289 | AY45: -0.69989341 | AZ45: -0.59739774 | BA45: -0.47917467 | BB45: -0.46321377 | BC45: -0.47260186 | BD45: -0.45380998 | BE45: -0.54538447 | BF45: -0.5258894 | BG45: -0.39605319 | BH45: -0.4084557 | BI45: -0.32396874 | BJ45: -0.25517809 | BK45: -0.1864792 | BL45: -0.26168153 | BM45: -0.1025051 | BN45: 0.010268886 | BO45: -0.042176291 | BP45: -0.040129971
A46: Cote d'Ivoire | B46: CIV | C46: Rule of Law: Estimate | D46: RL.EST | AO46: -0.78543514 | AQ46: -0.92291421 | AS46: -1.2476698 | AU46: -1.3292272 | AV46: -1.3585205 | AW46: -1.4245312 | AX46: -1.5393677 | AY46: -1.462904 | AZ46: -1.4717181 | BA46: -1.4381815 | BB46: -1.2530439 | BC46: -1.2360026 | BD46: -1.2826817 | BE46: -1.0941727 | BF46: -0.91469461 | BG46: -0.59325337 | BH46: -0.65147203 | BI46: -0.66303462 | BJ46: -0.65080386 | BK46: -0.60271031 | BL46: -0.61049551 | BM46: -0.65690857 | BN46: -0.66102356 | BO46: -0.47401825 | BP46: -0.46119714
A47: Cameroon | B47: CMR | C47: Rule of Law: Estimate | D47: RL.EST | AO47: -1.4418949 | AQ47: -1.1386371 | AS47: -1.1927472 | AU47: -1.2653756 | AV47: -1.1632996 | AW47: -1.1732225 | AX47: -1.1904403 | AY47: -1.1629846 | AZ47: -1.1858165 | BA47: -1.1058366 | BB47: -1.1309543 | BC47: -1.0792441 | BD47: -1.0808985 | BE47: -1.0429304 | BF47: -1.0583181 | BG47: -0.89785367 | BH47: -0.99832797 | BI47: -1.0590638 | BJ47: -1.051296 | BK47: -1.1030555 | BL47: -1.1414579 | BM47: -1.1676713 | BN47: -1.1164058 | BO47: -1.0389357 | BP47: -1.0381979
A48: Congo, Dem. Rep. | B48: COD | C48: Rule of Law: Estimate | D48: RL.EST | AO48: -1.8765634 | AQ48: -1.918399 | AS48: -1.8205644 | AU48: -1.7677203 | AV48: -1.8502527 | AW48: -1.7184352 | AX48: -1.5445285 | AY48: -1.6216967 | AZ48: -1.6147369 | BA48: -1.5736765 | BB48: -1.6440396 | BC48: -1.6271499 | BD48: -1.6255372 | BE48: -1.6629143 | BF48: -1.5850934 | BG48: -1.463033 | BH48: -1.6004239 | BI48: -1.6479818 | BJ48: -1.7110991 | BK48: -1.803568 | BL48: -1.8149027 | BM48: -1.823879 | BN48: -1.7238457 | BO48: -1.6717845 | BP48: -1.6707362
A49: Congo, Rep. | B49: COG | C49: Rule of Law: Estimate | D49: RL.EST | AO49: -1.04381 | AQ49: -1.6188086 | AS49: -1.3484983 | AU49: -1.2909853 | AV49: -1.2679707 | AW49: -1.1902502 | AX49: -1.4712036 | AY49: -1.2663457 | AZ49: -1.2232246 | BA49: -1.1934426 | BB49: -1.2201396 | BC49: -1.2180479 | BD49: -1.2075212 | BE49: -1.1420509 | BF49: -1.1212103 | BG49: -1.1192893 | BH49: -1.1360706 | BI49: -1.1495051 | BJ49: -1.1574285 | BK49: -1.1340642 | BL49: -1.1102204 | BM49: -1.1192163 | BN49: -1.0992813 | BO49: -1.0903462 | BP49: -1.0205873
A50: Colombia | B50: COL | C50: Rule of Law: Estimate | D50: RL.EST | AO50: -0.75183779 | AQ50: -0.66292048 | AS50: -0.92503792 | AU50: -0.74907309 | AV50: -0.73911756 | AW50: -0.69520015 | AX50: -0.63308185 | AY50: -0.50838792 | AZ50: -0.43298039 | BA50: -0.38123599 | BB50: -0.36777759 | BC50: -0.27138561 | BD50: -0.21736147 | BE50: -0.32591912 | BF50: -0.3882691 | BG50: -0.25229153 | BH50: -0.24723582 | BI50: -0.26606816 | BJ50: -0.36663327 | BK50: -0.38374215 | BL50: -0.39118397 | BM50: -0.49140263 | BN50: -0.4708285 | BO50: -0.42776024 | BP50: -0.45827293
A51: Comoros | B51: COM | C51: Rule of Law: Estimate | D51: RL.EST | AO51: -0.87860429 | AQ51: -0.88138592 | AS51: -1.1684276 | AU51: -0.74469298 | AV51: -0.75148177 | AW51: -1.0169219 | AX51: -1.0441906 | AY51: -0.97707474 | AZ51: -1.0396374 | BA51: -1.069914 | BB51: -1.1579722 | BC51: -1.0762305 | BD51: -1.0464748 | BE51: -1.0789295 | BF51: -0.95536774 | BG51: -0.89868683 | BH51: -0.85290754 | BI51: -1.0484173 | BJ51: -1.1025877 | BK51: -1.1428826 | BL51: -1.1572263 | BM51: -1.2769697 | BN51: -1.2578434 | BO51: -1.3146049 | BP51: -1.3412848
A52: Cabo Verde | B52: CPV | C52: Rule of Law: Estimate | D52: RL.EST | AO52: 1.0441881 | AQ52: 0.67207485 | AS52: 0.63842195 | AU52: 0.26743361 | AV52: 0.25637609 | AW52: 0.34184915 | AX52: 0.37414601 | AY52: 0.6402564 | AZ52: 0.61076552 | BA52: 0.57134515 | BB52: 0.53292972 | BC52: 0.46327785 | BD52: 0.50677043 | BE52: 0.51407009 | BF52: 0.5510661 | BG52: 0.66185224 | BH52: 0.56758755 | BI52: 0.28491557 | BJ52: 0.35290575 | BK52: 0.39306238 | BL52: 0.44679397 | BM52: 0.43083632 | BN52: 0.32773489 | BO52: 0.39866093 | BP52: 0.40010577
...
